Workbook
Name MULT_RETAIL_CONS: 'SKU with PRICES'!$Z$11
Name RATE_WHOLESALE_CONS: 'SKU with PRICES'!$Z$12
Name RATE_CORPORATE_CONS: 'SKU with PRICES'!$Z$13
Name RATE_INFLUENCER_CONS: 'SKU with PRICES'!$Z$14
Name VAT_REGISTERED: 'GUARDRAILS'!$C$7
Name R4_FLOOR: 'GUARDRAILS'!$C$8
Name MIN_TIER_RATE: 'GUARDRAILS'!$C$12
Name MULT_RETAIL: 'GUARDRAILS'!$C$14
Name MULT_RETAIL_CORE: 'GUARDRAILS'!$C$14
Name R4_MARKUP: 'GUARDRAILS'!$C$5
Name VAT_RATE: 'GUARDRAILS'!$C$6
Name TIER_WHOLESALE: 'GUARDRAILS'!$C$9
Name TIER_CORPORATE: 'GUARDRAILS'!$C$10
Name TIER_INFLUENCER: 'GUARDRAILS'!$C$11
Name SAFETY_BUFFER: 'GUARDRAILS'!$C$13
Name FX_USD_KES: 'GUARDRAILS'!$C$15
Name FREIGHT_RATE: 'GUARDRAILS'!$C$16
Name RATE_WHOLESALE: 'GUARDRAILS'!$C$9
Name RATE_CORPORATE: 'GUARDRAILS'!$C$10
Name RATE_INFLUENCER: 'GUARDRAILS'!$C$11
Name SHRINK_ACTUAL: 'GUARDRAILS'!$C$20
Name SHRINK_PLAN: 'GUARDRAILS'!$C$21
Name EVENT_COST: 'GUARDRAILS'!$C$22
Name UNITS_PER_EVENT: 'GUARDRAILS'!$C$23
Name FEE_BANK: 'GUARDRAILS'!$C$25
Name FEE_MPESA: 'GUARDRAILS'!$C$26
Name FEE_CASH: 'GUARDRAILS'!$C$27
Name MARKETING_MONTHLY: 'GUARDRAILS'!$C$29
Name ACT_EVENTS: 'GUARDRAILS'!$C$30
Name ACT_REVENUE_EST: 'GUARDRAILS'!$C$31
Name FIXED_MONTHLY: 'GUARDRAILS'!$C$28
Name AGENT_RATE: 'GUARDRAILS'!$C$24

Sheet FIXED_COSTS
A1: FIXED AND RECURRING COSTS — these were recorded all along
A2: I modelled FIXED_MONTHLY as 600 on 23 Sep and said salaries and warehouse rent were in no register. They were in the record from 9 September. That was my failure to search, and it understated the fixed base by a factor of 165.
A4: ITEM | B4: KES TOTAL | C4: PER MONTH | D4: PERIOD | E4: BASIS | F4: SOURCE / NOTE
A5: Salaries | B5: 344800 | C5: 86200 | D5: Jun-Sep 2026 | E5: EVIDENCED | F5: F-12, 9 Sep. Owner-funded personally, treated as a loan. No payroll registration, no PAYE record, no contracts — the most urgent compliance item in the estate.
A6: Warehouse rent | B6: 84000 | C6: 12000 | D6: Mar-Sep 2026 | E6: EVIDENCED | F6: F-11 / Q13c. Paid since Mar 2026, no written lease. First recurring fixed cost ever identified. Rent start and the 12 Mar count are almost certainly the same event — the anchor has a LOC_ID nobody wrote down.
A7: Bank maintenance | C7: 600 | D7: monthly | E7: EVIDENCED | F7: Incl. 20% excise. Transfer charges are separate, at ~0.69% of value moved.
A8: FIXED SUBTOTAL | C8: 98800 | D8: monthly | F8: salaries + warehouse + bank
A9: Activation SPACE | B9: 110000 | D9: Mar-Aug 2026 | E9: RULED | F9: Owner ruling 10 Sep. ~16 of 26 Saturdays used a paid venue; 10 were free or nominal.
A10: Activation STAFF | B10: 72000 | D10: Mar-Aug 2026 | E10: EVIDENCED | F10: 36 staff-days at 2,000. Reconciles exactly: 10 double-staffed + 16 single-staffed = 26 events.
A11: MARKETING SUBTOTAL | B11: 182000 | C11: 30333 | D11: 6 months | F11: Exactly 7,000 per event across 26 events
A12: TOTAL RECURRING | C12: 129133 | D12: monthly | F12: fixed + marketing
A13: Annualised | C13: 1549600 | D13: per year
A15: NOT YET IN HERE
A16: 1. Director's loan ~KES 923,000-1,331,000 — no agreement, no board minute, no ledger account.
A17: 2. aCatalyst balance 126,976, due ~28 Oct 2026. Against a 10 Sep bank balance of 75,849.45.
A18: 3. Digital consultancy 100,000 for two months, of which 50,000 has no receipt of any kind.
A19: 4. PAYE and statutory deductions — four months unfiled. Quantum unknown and not mine to estimate.
A20: 5. Transport, packaging and insurance — no figure anywhere.

Sheet BREAK_EVEN
A1: BREAK-EVEN — how much must sell before the month pays for itself
A2: Basket = one of each of the 31 publishable SKUs. Average price KES 6,677. Live against GUARDRAILS.
A4: SHRINKAGE | B4: CONTRIB MARGIN | C4: CONTRIB / UNIT | D4: UNITS / MONTH | E4: REVENUE / MONTH | F4: REVENUE / YEAR | G4: VERDICT
A5: historical 37.3% | B5: =(SUM(UNIT_ECONOMICS!$P$7:$P$37)-SUM(UNIT_ECONOMICS!$F$7:$F$37)-SUM(UNIT_ECONOMICS!$F$7:$F$37)*(SHRINK_ACTUAL/(1-SHRINK_ACTUAL))-SUM(UNIT_ECONOMICS!$P$7:$P$37)*FEE_MPESA)/SUM(UNIT_ECONOMICS!$P$7:$P$37) | C5: =(SUM(UNIT_ECONOMICS!$P$7:$P$37)-SUM(UNIT_ECONOMICS!$F$7:$F$37)-SUM(UNIT_ECONOMICS!$F$7:$F$37)*(SHRINK_ACTUAL/(1-SHRINK_ACTUAL))-SUM(UNIT_ECONOMICS!$P$7:$P$37)*FEE_MPESA)/31 | D5: =IF($C5<=0,"unreachable",ROUND((FIXED_MONTHLY+MARKETING_MONTHLY)/$C5,0)) | E5: =IF($B5<=0,"unreachable",ROUND((FIXED_MONTHLY+MARKETING_MONTHLY)/$B5,0)) | F5: =IF(ISNUMBER($E5),$E5*12,"unreachable") | G5: =IF(NOT(ISNUMBER($D5)),"impossible at any volume",IF($D5>100,"very hard","reachable"))
A6: plan 10% | B6: =(SUM(UNIT_ECONOMICS!$P$7:$P$37)-SUM(UNIT_ECONOMICS!$F$7:$F$37)-SUM(UNIT_ECONOMICS!$F$7:$F$37)*(SHRINK_PLAN/(1-SHRINK_PLAN))-SUM(UNIT_ECONOMICS!$P$7:$P$37)*FEE_MPESA)/SUM(UNIT_ECONOMICS!$P$7:$P$37) | C6: =(SUM(UNIT_ECONOMICS!$P$7:$P$37)-SUM(UNIT_ECONOMICS!$F$7:$F$37)-SUM(UNIT_ECONOMICS!$F$7:$F$37)*(SHRINK_PLAN/(1-SHRINK_PLAN))-SUM(UNIT_ECONOMICS!$P$7:$P$37)*FEE_MPESA)/31 | D6: =IF($C6<=0,"unreachable",ROUND((FIXED_MONTHLY+MARKETING_MONTHLY)/$C6,0)) | E6: =IF($B6<=0,"unreachable",ROUND((FIXED_MONTHLY+MARKETING_MONTHLY)/$B6,0)) | F6: =IF(ISNUMBER($E6),$E6*12,"unreachable") | G6: =IF(NOT(ISNUMBER($D6)),"impossible at any volume",IF($D6>100,"very hard","reachable"))
A7: best case 5% | B7: =(SUM(UNIT_ECONOMICS!$P$7:$P$37)-SUM(UNIT_ECONOMICS!$F$7:$F$37)-SUM(UNIT_ECONOMICS!$F$7:$F$37)*(0.05/(1-0.05))-SUM(UNIT_ECONOMICS!$P$7:$P$37)*FEE_MPESA)/SUM(UNIT_ECONOMICS!$P$7:$P$37) | C7: =(SUM(UNIT_ECONOMICS!$P$7:$P$37)-SUM(UNIT_ECONOMICS!$F$7:$F$37)-SUM(UNIT_ECONOMICS!$F$7:$F$37)*(0.05/(1-0.05))-SUM(UNIT_ECONOMICS!$P$7:$P$37)*FEE_MPESA)/31 | D7: =IF($C7<=0,"unreachable",ROUND((FIXED_MONTHLY+MARKETING_MONTHLY)/$C7,0)) | E7: =IF($B7<=0,"unreachable",ROUND((FIXED_MONTHLY+MARKETING_MONTHLY)/$B7,0)) | F7: =IF(ISNUMBER($E7),$E7*12,"unreachable") | G7: =IF(NOT(ISNUMBER($D7)),"impossible at any volume",IF($D7>100,"very hard","reachable"))
A9: All-time recorded Kenyan revenue, for scale | E9: 264862
A10: At plan shrinkage the business must sell more every MONTH than it has recorded in its entire life. That is the finding; it is not a pricing finding.
A12: ACTIVATION AS MARKETING — the payback test
A13: Owner ruling, 23 Sep 2026: activation is marketing, not a sales channel. It is no longer charged per unit. It must instead pay back as a programme.
A14: SHRINKAGE | B14: PROGRAMME COST | C14: REVENUE NEEDED | D14: REVENUE ESTIMATED | E14: CONTRIB GENERATED | F14: NET | G14: VERDICT
A15: historical 37.3% | B15: =MARKETING_MONTHLY*6 | C15: =ROUND($B15/((SUM(UNIT_ECONOMICS!$P$7:$P$37)-SUM(UNIT_ECONOMICS!$F$7:$F$37)-SUM(UNIT_ECONOMICS!$F$7:$F$37)*(SHRINK_ACTUAL/(1-SHRINK_ACTUAL))-SUM(UNIT_ECONOMICS!$P$7:$P$37)*FEE_MPESA)/SUM(UNIT_ECONOMICS!$P$7:$P$37)),0) | D15: =ACT_REVENUE_EST | E15: =ROUND($D15*((SUM(UNIT_ECONOMICS!$P$7:$P$37)-SUM(UNIT_ECONOMICS!$F$7:$F$37)-SUM(UNIT_ECONOMICS!$F$7:$F$37)*(SHRINK_ACTUAL/(1-SHRINK_ACTUAL))-SUM(UNIT_ECONOMICS!$P$7:$P$37)*FEE_MPESA)/SUM(UNIT_ECONOMICS!$P$7:$P$37)),0) | F15: =$E15-$B15 | G15: =IF($F15>=0,"PAYS BACK","SHORT "&TEXT(-$F15,"#,##0"))
A16: plan 10% | B16: =MARKETING_MONTHLY*6 | C16: =ROUND($B16/((SUM(UNIT_ECONOMICS!$P$7:$P$37)-SUM(UNIT_ECONOMICS!$F$7:$F$37)-SUM(UNIT_ECONOMICS!$F$7:$F$37)*(SHRINK_PLAN/(1-SHRINK_PLAN))-SUM(UNIT_ECONOMICS!$P$7:$P$37)*FEE_MPESA)/SUM(UNIT_ECONOMICS!$P$7:$P$37)),0) | D16: =ACT_REVENUE_EST | E16: =ROUND($D16*((SUM(UNIT_ECONOMICS!$P$7:$P$37)-SUM(UNIT_ECONOMICS!$F$7:$F$37)-SUM(UNIT_ECONOMICS!$F$7:$F$37)*(SHRINK_PLAN/(1-SHRINK_PLAN))-SUM(UNIT_ECONOMICS!$P$7:$P$37)*FEE_MPESA)/SUM(UNIT_ECONOMICS!$P$7:$P$37)),0) | F16: =$E16-$B16 | G16: =IF($F16>=0,"PAYS BACK","SHORT "&TEXT(-$F16,"#,##0"))
A17: best case 5% | B17: =MARKETING_MONTHLY*6 | C17: =ROUND($B17/((SUM(UNIT_ECONOMICS!$P$7:$P$37)-SUM(UNIT_ECONOMICS!$F$7:$F$37)-SUM(UNIT_ECONOMICS!$F$7:$F$37)*(0.05/(1-0.05))-SUM(UNIT_ECONOMICS!$P$7:$P$37)*FEE_MPESA)/SUM(UNIT_ECONOMICS!$P$7:$P$37)),0) | D17: =ACT_REVENUE_EST | E17: =ROUND($D17*((SUM(UNIT_ECONOMICS!$P$7:$P$37)-SUM(UNIT_ECONOMICS!$F$7:$F$37)-SUM(UNIT_ECONOMICS!$F$7:$F$37)*(0.05/(1-0.05))-SUM(UNIT_ECONOMICS!$P$7:$P$37)*FEE_MPESA)/SUM(UNIT_ECONOMICS!$P$7:$P$37)),0) | F17: =$E17-$B17 | G17: =IF($F17>=0,"PAYS BACK","SHORT "&TEXT(-$F17,"#,##0"))
A19: Reclassifying did not hide the problem — it sized it.
A20: Charged per unit the programme looked catastrophic (-49% margin), and about a third of that was a double-count of mine. Judged as marketing, at plan shrinkage it is short by about 30,000 over six months — within touching distance. At historical shrinkage it is short by 146,000 and no amount of marketing discipline reaches it. The same variable decides this as decides everything else.
A22: On RECORDED activation revenue of 5,700 the programme is short by ~180,000 at any shrinkage rate. The gap between 5,700 and 426,647 is the till statement, and it is still the single highest-value missing document.

Sheet UNIT_ECONOMICS
A1: UNIT ECONOMICS — what one unit actually leaves behind
A2: The R4 floor covers landed cost only. Everything right of GROSS is the cost of serving the unit. ACTIVATION IS NO LONGER CHARGED HERE — owner ruling 23 Sep: it is marketing. See BREAK_EVEN.
A4: CHANNEL | B4: RETAIL | C4: SHRINKAGE | D4: ACTUAL | E4: PAYMENT | F4: MPESA | H4: ACTIVATION? | I4: NO | J4: <- keep NO. Activation is a marketing programme now, tested on BREAK_EVEN.
A6: PARENT_SKU | B6: PRODUCT | C6: PRICE | D6: VAT OUT | E6: NET REV | F6: LANDED | G6: GROSS | H6: SHRINK | I6: PAY FEE | J6: AGENT | K6: EVENT | L6: CONTRIBUTION | M6: CONTR % | N6: VERDICT | P6: BASE_RETAIL
A7: UC-HOU-PHRO-001 | B7: =IFERROR(INDEX(GATE!$B:$B,MATCH($A7,GATE!$A:$A,0)),"") | C7: =IFERROR(INDEX(GATE!$G:$G,MATCH($A7,GATE!$A:$A,0))*IF($B$4="RETAIL",1,IF($B$4="WHOLESALE",TIER_WHOLESALE,IF($B$4="CORPORATE",TIER_CORPORATE,TIER_INFLUENCER))),"") | D7: =IF($C7="","",IF(VAT_REGISTERED="YES",ROUND($C7-$C7/(1+VAT_RATE),2),0)) | E7: =IF($C7="","",$C7-$D7) | F7: =IFERROR(INDEX(GATE!$D:$D,MATCH($A7,GATE!$A:$A,0)),"") | G7: =IF(OR($E7="",$F7=""),"",$E7-$F7) | H7: =IF($F7="","",ROUND(-$F7*(IF($D$4="ACTUAL",SHRINK_ACTUAL,SHRINK_PLAN)/(1-IF($D$4="ACTUAL",SHRINK_ACTUAL,SHRINK_PLAN))),2)) | I7: =IF($C7="","",ROUND(-$C7*IF($F$4="BANK",FEE_BANK,IF($F$4="MPESA",FEE_MPESA,FEE_CASH)),2)) | J7: =IF($C7="","",IF($I$4="YES",ROUND(-$C7*AGENT_RATE,2),0)) | K7: =IF($C7="","",IF($I$4="YES",ROUND(-EVENT_COST/UNITS_PER_EVENT,2),0)) | L7: =IF($G7="","",ROUND($G7+$H7+$I7+$J7+$K7,2)) | M7: =IF(OR($L7="",$C7=""),"",$L7/$C7) | N7: =IF($L7="","",IF($L7<0,"LOSS",IF($M7<0.15,"THIN","OK"))) | P7: =IFERROR(INDEX(GATE!$G:$G,MATCH($A7,GATE!$A:$A,0)),"")
A8: UC-HOU-URO-001 | B8: =IFERROR(INDEX(GATE!$B:$B,MATCH($A8,GATE!$A:$A,0)),"") | C8: =IFERROR(INDEX(GATE!$G:$G,MATCH($A8,GATE!$A:$A,0))*IF($B$4="RETAIL",1,IF($B$4="WHOLESALE",TIER_WHOLESALE,IF($B$4="CORPORATE",TIER_CORPORATE,TIER_INFLUENCER))),"") | D8: =IF($C8="","",IF(VAT_REGISTERED="YES",ROUND($C8-$C8/(1+VAT_RATE),2),0)) | E8: =IF($C8="","",$C8-$D8) | F8: =IFERROR(INDEX(GATE!$D:$D,MATCH($A8,GATE!$A:$A,0)),"") | G8: =IF(OR($E8="",$F8=""),"",$E8-$F8) | H8: =IF($F8="","",ROUND(-$F8*(IF($D$4="ACTUAL",SHRINK_ACTUAL,SHRINK_PLAN)/(1-IF($D$4="ACTUAL",SHRINK_ACTUAL,SHRINK_PLAN))),2)) | I8: =IF($C8="","",ROUND(-$C8*IF($F$4="BANK",FEE_BANK,IF($F$4="MPESA",FEE_MPESA,FEE_CASH)),2)) | J8: =IF($C8="","",IF($I$4="YES",ROUND(-$C8*AGENT_RATE,2),0)) | K8: =IF($C8="","",IF($I$4="YES",ROUND(-EVENT_COST/UNITS_PER_EVENT,2),0)) | L8: =IF($G8="","",ROUND($G8+$H8+$I8+$J8+$K8,2)) | M8: =IF(OR($L8="",$C8=""),"",$L8/$C8) | N8: =IF($L8="","",IF($L8<0,"LOSS",IF($M8<0.15,"THIN","OK"))) | P8: =IFERROR(INDEX(GATE!$G:$G,MATCH($A8,GATE!$A:$A,0)),"")
A9: UC-HOU-URO-002 | B9: =IFERROR(INDEX(GATE!$B:$B,MATCH($A9,GATE!$A:$A,0)),"") | C9: =IFERROR(INDEX(GATE!$G:$G,MATCH($A9,GATE!$A:$A,0))*IF($B$4="RETAIL",1,IF($B$4="WHOLESALE",TIER_WHOLESALE,IF($B$4="CORPORATE",TIER_CORPORATE,TIER_INFLUENCER))),"") | D9: =IF($C9="","",IF(VAT_REGISTERED="YES",ROUND($C9-$C9/(1+VAT_RATE),2),0)) | E9: =IF($C9="","",$C9-$D9) | F9: =IFERROR(INDEX(GATE!$D:$D,MATCH($A9,GATE!$A:$A,0)),"") | G9: =IF(OR($E9="",$F9=""),"",$E9-$F9) | H9: =IF($F9="","",ROUND(-$F9*(IF($D$4="ACTUAL",SHRINK_ACTUAL,SHRINK_PLAN)/(1-IF($D$4="ACTUAL",SHRINK_ACTUAL,SHRINK_PLAN))),2)) | I9: =IF($C9="","",ROUND(-$C9*IF($F$4="BANK",FEE_BANK,IF($F$4="MPESA",FEE_MPESA,FEE_CASH)),2)) | J9: =IF($C9="","",IF($I$4="YES",ROUND(-$C9*AGENT_RATE,2),0)) | K9: =IF($C9="","",IF($I$4="YES",ROUND(-EVENT_COST/UNITS_PER_EVENT,2),0)) | L9: =IF($G9="","",ROUND($G9+$H9+$I9+$J9+$K9,2)) | M9: =IF(OR($L9="",$C9=""),"",$L9/$C9) | N9: =IF($L9="","",IF($L9<0,"LOSS",IF($M9<0.15,"THIN","OK"))) | P9: =IFERROR(INDEX(GATE!$G:$G,MATCH($A9,GATE!$A:$A,0)),"")
A10: UC-HOU-ROS-001 | B10: =IFERROR(INDEX(GATE!$B:$B,MATCH($A10,GATE!$A:$A,0)),"") | C10: =IFERROR(INDEX(GATE!$G:$G,MATCH($A10,GATE!$A:$A,0))*IF($B$4="RETAIL",1,IF($B$4="WHOLESALE",TIER_WHOLESALE,IF($B$4="CORPORATE",TIER_CORPORATE,TIER_INFLUENCER))),"") | D10: =IF($C10="","",IF(VAT_REGISTERED="YES",ROUND($C10-$C10/(1+VAT_RATE),2),0)) | E10: =IF($C10="","",$C10-$D10) | F10: =IFERROR(INDEX(GATE!$D:$D,MATCH($A10,GATE!$A:$A,0)),"") | G10: =IF(OR($E10="",$F10=""),"",$E10-$F10) | H10: =IF($F10="","",ROUND(-$F10*(IF($D$4="ACTUAL",SHRINK_ACTUAL,SHRINK_PLAN)/(1-IF($D$4="ACTUAL",SHRINK_ACTUAL,SHRINK_PLAN))),2)) | I10: =IF($C10="","",ROUND(-$C10*IF($F$4="BANK",FEE_BANK,IF($F$4="MPESA",FEE_MPESA,FEE_CASH)),2)) | J10: =IF($C10="","",IF($I$4="YES",ROUND(-$C10*AGENT_RATE,2),0)) | K10: =IF($C10="","",IF($I$4="YES",ROUND(-EVENT_COST/UNITS_PER_EVENT,2),0)) | L10: =IF($G10="","",ROUND($G10+$H10+$I10+$J10+$K10,2)) | M10: =IF(OR($L10="",$C10=""),"",$L10/$C10) | N10: =IF($L10="","",IF($L10<0,"LOSS",IF($M10<0.15,"THIN","OK"))) | P10: =IFERROR(INDEX(GATE!$G:$G,MATCH($A10,GATE!$A:$A,0)),"")
A11: UC-COM-ROS-002 | B11: =IFERROR(INDEX(GATE!$B:$B,MATCH($A11,GATE!$A:$A,0)),"") | C11: =IFERROR(INDEX(GATE!$G:$G,MATCH($A11,GATE!$A:$A,0))*IF($B$4="RETAIL",1,IF($B$4="WHOLESALE",TIER_WHOLESALE,IF($B$4="CORPORATE",TIER_CORPORATE,TIER_INFLUENCER))),"") | D11: =IF($C11="","",IF(VAT_REGISTERED="YES",ROUND($C11-$C11/(1+VAT_RATE),2),0)) | E11: =IF($C11="","",$C11-$D11) | F11: =IFERROR(INDEX(GATE!$D:$D,MATCH($A11,GATE!$A:$A,0)),"") | G11: =IF(OR($E11="",$F11=""),"",$E11-$F11) | H11: =IF($F11="","",ROUND(-$F11*(IF($D$4="ACTUAL",SHRINK_ACTUAL,SHRINK_PLAN)/(1-IF($D$4="ACTUAL",SHRINK_ACTUAL,SHRINK_PLAN))),2)) | I11: =IF($C11="","",ROUND(-$C11*IF($F$4="BANK",FEE_BANK,IF($F$4="MPESA",FEE_MPESA,FEE_CASH)),2)) | J11: =IF($C11="","",IF($I$4="YES",ROUND(-$C11*AGENT_RATE,2),0)) | K11: =IF($C11="","",IF($I$4="YES",ROUND(-EVENT_COST/UNITS_PER_EVENT,2),0)) | L11: =IF($G11="","",ROUND($G11+$H11+$I11+$J11+$K11,2)) | M11: =IF(OR($L11="",$C11=""),"",$L11/$C11) | N11: =IF($L11="","",IF($L11<0,"LOSS",IF($M11<0.15,"THIN","OK"))) | P11: =IFERROR(INDEX(GATE!$G:$G,MATCH($A11,GATE!$A:$A,0)),"")
A12: UC-HOU-WPF-003 | B12: =IFERROR(INDEX(GATE!$B:$B,MATCH($A12,GATE!$A:$A,0)),"") | C12: =IFERROR(INDEX(GATE!$G:$G,MATCH($A12,GATE!$A:$A,0))*IF($B$4="RETAIL",1,IF($B$4="WHOLESALE",TIER_WHOLESALE,IF($B$4="CORPORATE",TIER_CORPORATE,TIER_INFLUENCER))),"") | D12: =IF($C12="","",IF(VAT_REGISTERED="YES",ROUND($C12-$C12/(1+VAT_RATE),2),0)) | E12: =IF($C12="","",$C12-$D12) | F12: =IFERROR(INDEX(GATE!$D:$D,MATCH($A12,GATE!$A:$A,0)),"") | G12: =IF(OR($E12="",$F12=""),"",$E12-$F12) | H12: =IF($F12="","",ROUND(-$F12*(IF($D$4="ACTUAL",SHRINK_ACTUAL,SHRINK_PLAN)/(1-IF($D$4="ACTUAL",SHRINK_ACTUAL,SHRINK_PLAN))),2)) | I12: =IF($C12="","",ROUND(-$C12*IF($F$4="BANK",FEE_BANK,IF($F$4="MPESA",FEE_MPESA,FEE_CASH)),2)) | J12: =IF($C12="","",IF($I$4="YES",ROUND(-$C12*AGENT_RATE,2),0)) | K12: =IF($C12="","",IF($I$4="YES",ROUND(-EVENT_COST/UNITS_PER_EVENT,2),0)) | L12: =IF($G12="","",ROUND($G12+$H12+$I12+$J12+$K12,2)) | M12: =IF(OR($L12="",$C12=""),"",$L12/$C12) | N12: =IF($L12="","",IF($L12<0,"LOSS",IF($M12<0.15,"THIN","OK"))) | P12: =IFERROR(INDEX(GATE!$G:$G,MATCH($A12,GATE!$A:$A,0)),"")
A13: UC-HOU-USF-004 | B13: =IFERROR(INDEX(GATE!$B:$B,MATCH($A13,GATE!$A:$A,0)),"") | C13: =IFERROR(INDEX(GATE!$G:$G,MATCH($A13,GATE!$A:$A,0))*IF($B$4="RETAIL",1,IF($B$4="WHOLESALE",TIER_WHOLESALE,IF($B$4="CORPORATE",TIER_CORPORATE,TIER_INFLUENCER))),"") | D13: =IF($C13="","",IF(VAT_REGISTERED="YES",ROUND($C13-$C13/(1+VAT_RATE),2),0)) | E13: =IF($C13="","",$C13-$D13) | F13: =IFERROR(INDEX(GATE!$D:$D,MATCH($A13,GATE!$A:$A,0)),"") | G13: =IF(OR($E13="",$F13=""),"",$E13-$F13) | H13: =IF($F13="","",ROUND(-$F13*(IF($D$4="ACTUAL",SHRINK_ACTUAL,SHRINK_PLAN)/(1-IF($D$4="ACTUAL",SHRINK_ACTUAL,SHRINK_PLAN))),2)) | I13: =IF($C13="","",ROUND(-$C13*IF($F$4="BANK",FEE_BANK,IF($F$4="MPESA",FEE_MPESA,FEE_CASH)),2)) | J13: =IF($C13="","",IF($I$4="YES",ROUND(-$C13*AGENT_RATE,2),0)) | K13: =IF($C13="","",IF($I$4="YES",ROUND(-EVENT_COST/UNITS_PER_EVENT,2),0)) | L13: =IF($G13="","",ROUND($G13+$H13+$I13+$J13+$K13,2)) | M13: =IF(OR($L13="",$C13=""),"",$L13/$C13) | N13: =IF($L13="","",IF($L13<0,"LOSS",IF($M13<0.15,"THIN","OK"))) | P13: =IFERROR(INDEX(GATE!$G:$G,MATCH($A13,GATE!$A:$A,0)),"")
A14: UC-HOU-TAP-005 | B14: =IFERROR(INDEX(GATE!$B:$B,MATCH($A14,GATE!$A:$A,0)),"") | C14: =IFERROR(INDEX(GATE!$G:$G,MATCH($A14,GATE!$A:$A,0))*IF($B$4="RETAIL",1,IF($B$4="WHOLESALE",TIER_WHOLESALE,IF($B$4="CORPORATE",TIER_CORPORATE,TIER_INFLUENCER))),"") | D14: =IF($C14="","",IF(VAT_REGISTERED="YES",ROUND($C14-$C14/(1+VAT_RATE),2),0)) | E14: =IF($C14="","",$C14-$D14) | F14: =IFERROR(INDEX(GATE!$D:$D,MATCH($A14,GATE!$A:$A,0)),"") | G14: =IF(OR($E14="",$F14=""),"",$E14-$F14) | H14: =IF($F14="","",ROUND(-$F14*(IF($D$4="ACTUAL",SHRINK_ACTUAL,SHRINK_PLAN)/(1-IF($D$4="ACTUAL",SHRINK_ACTUAL,SHRINK_PLAN))),2)) | I14: =IF($C14="","",ROUND(-$C14*IF($F$4="BANK",FEE_BANK,IF($F$4="MPESA",FEE_MPESA,FEE_CASH)),2)) | J14: =IF($C14="","",IF($I$4="YES",ROUND(-$C14*AGENT_RATE,2),0)) | K14: =IF($C14="","",IF($I$4="YES",ROUND(-EVENT_COST/UNITS_PER_EVENT,2),0)) | L14: =IF($G14="","",ROUND($G14+$H14+$I14+$J14+$K14,2)) | M14: =IF(OR($L14="",$C14=""),"",$L14/$C14) | N14: =IF($L14="","",IF($L14<0,"LOSS",IF($M14<0.15,"THIN","OK"))) | P14: =IFERROR(INDEX(GATE!$G:$G,MATCH($A14,GATE!$A:$A,0)),"")
A15: UC-HOU-TAPF-006 | B15: =IFERROR(INDEX(GATE!$B:$B,MATCH($A15,GATE!$A:$A,0)),"") | C15: =IFERROR(INDEX(GATE!$G:$G,MATCH($A15,GATE!$A:$A,0))*IF($B$4="RETAIL",1,IF($B$4="WHOLESALE",TIER_WHOLESALE,IF($B$4="CORPORATE",TIER_CORPORATE,TIER_INFLUENCER))),"") | D15: =IF($C15="","",IF(VAT_REGISTERED="YES",ROUND($C15-$C15/(1+VAT_RATE),2),0)) | E15: =IF($C15="","",$C15-$D15) | F15: =IFERROR(INDEX(GATE!$D:$D,MATCH($A15,GATE!$A:$A,0)),"") | G15: =IF(OR($E15="",$F15=""),"",$E15-$F15) | H15: =IF($F15="","",ROUND(-$F15*(IF($D$4="ACTUAL",SHRINK_ACTUAL,SHRINK_PLAN)/(1-IF($D$4="ACTUAL",SHRINK_ACTUAL,SHRINK_PLAN))),2)) | I15: =IF($C15="","",ROUND(-$C15*IF($F$4="BANK",FEE_BANK,IF($F$4="MPESA",FEE_MPESA,FEE_CASH)),2)) | J15: =IF($C15="","",IF($I$4="YES",ROUND(-$C15*AGENT_RATE,2),0)) | K15: =IF($C15="","",IF($I$4="YES",ROUND(-EVENT_COST/UNITS_PER_EVENT,2),0)) | L15: =IF($G15="","",ROUND($G15+$H15+$I15+$J15+$K15,2)) | M15: =IF(OR($L15="",$C15=""),"",$L15/$C15) | N15: =IF($L15="","",IF($L15<0,"LOSS",IF($M15<0.15,"THIN","OK"))) | P15: =IFERROR(INDEX(GATE!$G:$G,MATCH($A15,GATE!$A:$A,0)),"")
A16: UC-HOU-WDFS-006 | B16: =IFERROR(INDEX(GATE!$B:$B,MATCH($A16,GATE!$A:$A,0)),"") | C16: =IFERROR(INDEX(GATE!$G:$G,MATCH($A16,GATE!$A:$A,0))*IF($B$4="RETAIL",1,IF($B$4="WHOLESALE",TIER_WHOLESALE,IF($B$4="CORPORATE",TIER_CORPORATE,TIER_INFLUENCER))),"") | D16: =IF($C16="","",IF(VAT_REGISTERED="YES",ROUND($C16-$C16/(1+VAT_RATE),2),0)) | E16: =IF($C16="","",$C16-$D16) | F16: =IFERROR(INDEX(GATE!$D:$D,MATCH($A16,GATE!$A:$A,0)),"") | G16: =IF(OR($E16="",$F16=""),"",$E16-$F16) | H16: =IF($F16="","",ROUND(-$F16*(IF($D$4="ACTUAL",SHRINK_ACTUAL,SHRINK_PLAN)/(1-IF($D$4="ACTUAL",SHRINK_ACTUAL,SHRINK_PLAN))),2)) | I16: =IF($C16="","",ROUND(-$C16*IF($F$4="BANK",FEE_BANK,IF($F$4="MPESA",FEE_MPESA,FEE_CASH)),2)) | J16: =IF($C16="","",IF($I$4="YES",ROUND(-$C16*AGENT_RATE,2),0)) | K16: =IF($C16="","",IF($I$4="YES",ROUND(-EVENT_COST/UNITS_PER_EVENT,2),0)) | L16: =IF($G16="","",ROUND($G16+$H16+$I16+$J16+$K16,2)) | M16: =IF(OR($L16="",$C16=""),"",$L16/$C16) | N16: =IF($L16="","",IF($L16<0,"LOSS",IF($M16<0.15,"THIN","OK"))) | P16: =IFERROR(INDEX(GATE!$G:$G,MATCH($A16,GATE!$A:$A,0)),"")
A17: UC-HOU-DF-007 | B17: =IFERROR(INDEX(GATE!$B:$B,MATCH($A17,GATE!$A:$A,0)),"") | C17: =IFERROR(INDEX(GATE!$G:$G,MATCH($A17,GATE!$A:$A,0))*IF($B$4="RETAIL",1,IF($B$4="WHOLESALE",TIER_WHOLESALE,IF($B$4="CORPORATE",TIER_CORPORATE,TIER_INFLUENCER))),"") | D17: =IF($C17="","",IF(VAT_REGISTERED="YES",ROUND($C17-$C17/(1+VAT_RATE),2),0)) | E17: =IF($C17="","",$C17-$D17) | F17: =IFERROR(INDEX(GATE!$D:$D,MATCH($A17,GATE!$A:$A,0)),"") | G17: =IF(OR($E17="",$F17=""),"",$E17-$F17) | H17: =IF($F17="","",ROUND(-$F17*(IF($D$4="ACTUAL",SHRINK_ACTUAL,SHRINK_PLAN)/(1-IF($D$4="ACTUAL",SHRINK_ACTUAL,SHRINK_PLAN))),2)) | I17: =IF($C17="","",ROUND(-$C17*IF($F$4="BANK",FEE_BANK,IF($F$4="MPESA",FEE_MPESA,FEE_CASH)),2)) | J17: =IF($C17="","",IF($I$4="YES",ROUND(-$C17*AGENT_RATE,2),0)) | K17: =IF($C17="","",IF($I$4="YES",ROUND(-EVENT_COST/UNITS_PER_EVENT,2),0)) | L17: =IF($G17="","",ROUND($G17+$H17+$I17+$J17+$K17,2)) | M17: =IF(OR($L17="",$C17=""),"",$L17/$C17) | N17: =IF($L17="","",IF($L17<0,"LOSS",IF($M17<0.15,"THIN","OK"))) | P17: =IFERROR(INDEX(GATE!$G:$G,MATCH($A17,GATE!$A:$A,0)),"")
A18: UC-BOG-SSB-008 | B18: =IFERROR(INDEX(GATE!$B:$B,MATCH($A18,GATE!$A:$A,0)),"") | C18: =IFERROR(INDEX(GATE!$G:$G,MATCH($A18,GATE!$A:$A,0))*IF($B$4="RETAIL",1,IF($B$4="WHOLESALE",TIER_WHOLESALE,IF($B$4="CORPORATE",TIER_CORPORATE,TIER_INFLUENCER))),"") | D18: =IF($C18="","",IF(VAT_REGISTERED="YES",ROUND($C18-$C18/(1+VAT_RATE),2),0)) | E18: =IF($C18="","",$C18-$D18) | F18: =IFERROR(INDEX(GATE!$D:$D,MATCH($A18,GATE!$A:$A,0)),"") | G18: =IF(OR($E18="",$F18=""),"",$E18-$F18) | H18: =IF($F18="","",ROUND(-$F18*(IF($D$4="ACTUAL",SHRINK_ACTUAL,SHRINK_PLAN)/(1-IF($D$4="ACTUAL",SHRINK_ACTUAL,SHRINK_PLAN))),2)) | I18: =IF($C18="","",ROUND(-$C18*IF($F$4="BANK",FEE_BANK,IF($F$4="MPESA",FEE_MPESA,FEE_CASH)),2)) | J18: =IF($C18="","",IF($I$4="YES",ROUND(-$C18*AGENT_RATE,2),0)) | K18: =IF($C18="","",IF($I$4="YES",ROUND(-EVENT_COST/UNITS_PER_EVENT,2),0)) | L18: =IF($G18="","",ROUND($G18+$H18+$I18+$J18+$K18,2)) | M18: =IF(OR($L18="",$C18=""),"",$L18/$C18) | N18: =IF($L18="","",IF($L18<0,"LOSS",IF($M18<0.15,"THIN","OK"))) | P18: =IFERROR(INDEX(GATE!$G:$G,MATCH($A18,GATE!$A:$A,0)),"")
... A37: UC-BOG-ECO-ECF1 | B37: =IFERROR(INDEX(GATE!$B:$B,MATCH($A37,GATE!$A:$A,0)),"") | C37: =IFERROR(INDEX(GATE!$G:$G,MATCH($A37,GATE!$A:$A,0))*IF($B$4="RETAIL",1,IF($B$4="WHOLESALE",TIER_WHOLESALE,IF($B$4="CORPORATE",TIER_CORPORATE,TIER_INFLUENCER))),"") | D37: =IF($C37="","",IF(VAT_REGISTERED="YES",ROUND($C37-$C37/(1+VAT_RATE),2),0)) | E37: =IF($C37="","",$C37-$D37) | F37: =IFERROR(INDEX(GATE!$D:$D,MATCH($A37,GATE!$A:$A,0)),"") | G37: =IF(OR($E37="",$F37=""),"",$E37-$F37) | H37: =IF($F37="","",ROUND(-$F37*(IF($D$4="ACTUAL",SHRINK_ACTUAL,SHRINK_PLAN)/(1-IF($D$4="ACTUAL",SHRINK_ACTUAL,SHRINK_PLAN))),2)) | I37: =IF($C37="","",ROUND(-$C37*IF($F$4="BANK",FEE_BANK,IF($F$4="MPESA",FEE_MPESA,FEE_CASH)),2)) | J37: =IF($C37="","",IF($I$4="YES",ROUND(-$C37*AGENT_RATE,2),0)) | K37: =IF($C37="","",IF($I$4="YES",ROUND(-EVENT_COST/UNITS_PER_EVENT,2),0)) | L37: =IF($G37="","",ROUND($G37+$H37+$I37+$J37+$K37,2)) | M37: =IF(OR($L37="",$C37=""),"",$L37/$C37) | N37: =IF($L37="","",IF($L37<0,"LOSS",IF($M37<0.15,"THIN","OK"))) | P37: =IFERROR(INDEX(GATE!$G:$G,MATCH($A37,GATE!$A:$A,0)),"")
B39: TOTALS / AVERAGE | C39: =SUM(C7:C37) | F39: =SUM(F7:F37) | G39: =SUM(G7:G37) | H39: =SUM(H7:H37) | I39: =SUM(I7:I37) | J39: =SUM(J7:J37) | K39: =SUM(K7:K37) | L39: =SUM(L7:L37) | M39: =IF($C39=0,"",$L39/$C39)
B41: LOSS | C41: =COUNTIF($N$7:$N$37,"LOSS")
B42: THIN | C42: =COUNTIF($N$7:$N$37,"THIN")
B43: OK | C43: =COUNTIF($N$7:$N$37,"OK")

Sheet CHANNEL_ECONOMICS
A1: CHANNEL ECONOMICS — the same basket sold five ways, at three shrinkage rates
A2: One unit of every publishable SKU (31 products). Live: change any parameter on GUARDRAILS and every cell below moves.
A4: CHANNEL | B4: SHRINKAGE | C4: REVENUE | D4: LANDED | E4: GROSS | F4: SHRINK LOSS | G4: PAY FEE | H4: AGENT | I4: EVENT | J4: CONTRIBUTION | K4: MARGIN | L4: VERDICT
A5: Retail walk-in | B5: historical 37.3% | C5: =SUM(UNIT_ECONOMICS!$P$7:$P$37)*1 | D5: =SUM(UNIT_ECONOMICS!$F$7:$F$37) | E5: =$C5-$D5 | F5: =-$D5*(SHRINK_ACTUAL/(1-SHRINK_ACTUAL)) | G5: =-$C5*FEE_MPESA | H5: =-$C5*AGENT_RATE*0 | I5: =-31*EVENT_COST/UNITS_PER_EVENT*0 | J5: =SUM($E5:$I5) | K5: =IF($C5=0,"",$J5/$C5) | L5: =IF($J5<0,"LOSS",IF($K5<0.15,"THIN","OK"))
B6: plan 10% | C6: =SUM(UNIT_ECONOMICS!$P$7:$P$37)*1 | D6: =SUM(UNIT_ECONOMICS!$F$7:$F$37) | E6: =$C6-$D6 | F6: =-$D6*(SHRINK_PLAN/(1-SHRINK_PLAN)) | G6: =-$C6*FEE_MPESA | H6: =-$C6*AGENT_RATE*0 | I6: =-31*EVENT_COST/UNITS_PER_EVENT*0 | J6: =SUM($E6:$I6) | K6: =IF($C6=0,"",$J6/$C6) | L6: =IF($J6<0,"LOSS",IF($K6<0.15,"THIN","OK"))
B7: best case 5% | C7: =SUM(UNIT_ECONOMICS!$P$7:$P$37)*1 | D7: =SUM(UNIT_ECONOMICS!$F$7:$F$37) | E7: =$C7-$D7 | F7: =-$D7*(0.05/(1-0.05)) | G7: =-$C7*FEE_MPESA | H7: =-$C7*AGENT_RATE*0 | I7: =-31*EVENT_COST/UNITS_PER_EVENT*0 | J7: =SUM($E7:$I7) | K7: =IF($C7=0,"",$J7/$C7) | L7: =IF($J7<0,"LOSS",IF($K7<0.15,"THIN","OK"))
A8: Activation (agent + event) | B8: historical 37.3% | C8: =SUM(UNIT_ECONOMICS!$P$7:$P$37)*1 | D8: =SUM(UNIT_ECONOMICS!$F$7:$F$37) | E8: =$C8-$D8 | F8: =-$D8*(SHRINK_ACTUAL/(1-SHRINK_ACTUAL)) | G8: =-$C8*FEE_MPESA | H8: =-$C8*AGENT_RATE*1 | I8: =-31*EVENT_COST/UNITS_PER_EVENT*1 | J8: =SUM($E8:$I8) | K8: =IF($C8=0,"",$J8/$C8) | L8: =IF($J8<0,"LOSS",IF($K8<0.15,"THIN","OK"))
B9: plan 10% | C9: =SUM(UNIT_ECONOMICS!$P$7:$P$37)*1 | D9: =SUM(UNIT_ECONOMICS!$F$7:$F$37) | E9: =$C9-$D9 | F9: =-$D9*(SHRINK_PLAN/(1-SHRINK_PLAN)) | G9: =-$C9*FEE_MPESA | H9: =-$C9*AGENT_RATE*1 | I9: =-31*EVENT_COST/UNITS_PER_EVENT*1 | J9: =SUM($E9:$I9) | K9: =IF($C9=0,"",$J9/$C9) | L9: =IF($J9<0,"LOSS",IF($K9<0.15,"THIN","OK"))
B10: best case 5% | C10: =SUM(UNIT_ECONOMICS!$P$7:$P$37)*1 | D10: =SUM(UNIT_ECONOMICS!$F$7:$F$37) | E10: =$C10-$D10 | F10: =-$D10*(0.05/(1-0.05)) | G10: =-$C10*FEE_MPESA | H10: =-$C10*AGENT_RATE*1 | I10: =-31*EVENT_COST/UNITS_PER_EVENT*1 | J10: =SUM($E10:$I10) | K10: =IF($C10=0,"",$J10/$C10) | L10: =IF($J10<0,"LOSS",IF($K10<0.15,"THIN","OK"))
A11: Wholesale | B11: historical 37.3% | C11: =SUM(UNIT_ECONOMICS!$P$7:$P$37)*TIER_WHOLESALE | D11: =SUM(UNIT_ECONOMICS!$F$7:$F$37) | E11: =$C11-$D11 | F11: =-$D11*(SHRINK_ACTUAL/(1-SHRINK_ACTUAL)) | G11: =-$C11*FEE_BANK | H11: =-$C11*AGENT_RATE*0 | I11: =-31*EVENT_COST/UNITS_PER_EVENT*0 | J11: =SUM($E11:$I11) | K11: =IF($C11=0,"",$J11/$C11) | L11: =IF($J11<0,"LOSS",IF($K11<0.15,"THIN","OK"))
B12: plan 10% | C12: =SUM(UNIT_ECONOMICS!$P$7:$P$37)*TIER_WHOLESALE | D12: =SUM(UNIT_ECONOMICS!$F$7:$F$37) | E12: =$C12-$D12 | F12: =-$D12*(SHRINK_PLAN/(1-SHRINK_PLAN)) | G12: =-$C12*FEE_BANK | H12: =-$C12*AGENT_RATE*0 | I12: =-31*EVENT_COST/UNITS_PER_EVENT*0 | J12: =SUM($E12:$I12) | K12: =IF($C12=0,"",$J12/$C12) | L12: =IF($J12<0,"LOSS",IF($K12<0.15,"THIN","OK"))
B13: best case 5% | C13: =SUM(UNIT_ECONOMICS!$P$7:$P$37)*TIER_WHOLESALE | D13: =SUM(UNIT_ECONOMICS!$F$7:$F$37) | E13: =$C13-$D13 | F13: =-$D13*(0.05/(1-0.05)) | G13: =-$C13*FEE_BANK | H13: =-$C13*AGENT_RATE*0 | I13: =-31*EVENT_COST/UNITS_PER_EVENT*0 | J13: =SUM($E13:$I13) | K13: =IF($C13=0,"",$J13/$C13) | L13: =IF($J13<0,"LOSS",IF($K13<0.15,"THIN","OK"))
A14: Corporate | B14: historical 37.3% | C14: =SUM(UNIT_ECONOMICS!$P$7:$P$37)*TIER_CORPORATE | D14: =SUM(UNIT_ECONOMICS!$F$7:$F$37) | E14: =$C14-$D14 | F14: =-$D14*(SHRINK_ACTUAL/(1-SHRINK_ACTUAL)) | G14: =-$C14*FEE_BANK | H14: =-$C14*AGENT_RATE*0 | I14: =-31*EVENT_COST/UNITS_PER_EVENT*0 | J14: =SUM($E14:$I14) | K14: =IF($C14=0,"",$J14/$C14) | L14: =IF($J14<0,"LOSS",IF($K14<0.15,"THIN","OK"))
B15: plan 10% | C15: =SUM(UNIT_ECONOMICS!$P$7:$P$37)*TIER_CORPORATE | D15: =SUM(UNIT_ECONOMICS!$F$7:$F$37) | E15: =$C15-$D15 | F15: =-$D15*(SHRINK_PLAN/(1-SHRINK_PLAN)) | G15: =-$C15*FEE_BANK | H15: =-$C15*AGENT_RATE*0 | I15: =-31*EVENT_COST/UNITS_PER_EVENT*0 | J15: =SUM($E15:$I15) | K15: =IF($C15=0,"",$J15/$C15) | L15: =IF($J15<0,"LOSS",IF($K15<0.15,"THIN","OK"))
B16: best case 5% | C16: =SUM(UNIT_ECONOMICS!$P$7:$P$37)*TIER_CORPORATE | D16: =SUM(UNIT_ECONOMICS!$F$7:$F$37) | E16: =$C16-$D16 | F16: =-$D16*(0.05/(1-0.05)) | G16: =-$C16*FEE_BANK | H16: =-$C16*AGENT_RATE*0 | I16: =-31*EVENT_COST/UNITS_PER_EVENT*0 | J16: =SUM($E16:$I16) | K16: =IF($C16=0,"",$J16/$C16) | L16: =IF($J16<0,"LOSS",IF($K16<0.15,"THIN","OK"))
A17: Influencer | B17: historical 37.3% | C17: =SUM(UNIT_ECONOMICS!$P$7:$P$37)*TIER_INFLUENCER | D17: =SUM(UNIT_ECONOMICS!$F$7:$F$37) | E17: =$C17-$D17 | F17: =-$D17*(SHRINK_ACTUAL/(1-SHRINK_ACTUAL)) | G17: =-$C17*FEE_MPESA | H17: =-$C17*AGENT_RATE*0 | I17: =-31*EVENT_COST/UNITS_PER_EVENT*0 | J17: =SUM($E17:$I17) | K17: =IF($C17=0,"",$J17/$C17) | L17: =IF($J17<0,"LOSS",IF($K17<0.15,"THIN","OK"))
B18: plan 10% | C18: =SUM(UNIT_ECONOMICS!$P$7:$P$37)*TIER_INFLUENCER | D18: =SUM(UNIT_ECONOMICS!$F$7:$F$37) | E18: =$C18-$D18 | F18: =-$D18*(SHRINK_PLAN/(1-SHRINK_PLAN)) | G18: =-$C18*FEE_MPESA | H18: =-$C18*AGENT_RATE*0 | I18: =-31*EVENT_COST/UNITS_PER_EVENT*0 | J18: =SUM($E18:$I18) | K18: =IF($C18=0,"",$J18/$C18) | L18: =IF($J18<0,"LOSS",IF($K18<0.15,"THIN","OK"))
B19: best case 5% | C19: =SUM(UNIT_ECONOMICS!$P$7:$P$37)*TIER_INFLUENCER | D19: =SUM(UNIT_ECONOMICS!$F$7:$F$37) | E19: =$C19-$D19 | F19: =-$D19*(0.05/(1-0.05)) | G19: =-$C19*FEE_MPESA | H19: =-$C19*AGENT_RATE*0 | I19: =-31*EVENT_COST/UNITS_PER_EVENT*0 | J19: =SUM($E19:$I19) | K19: =IF($C19=0,"",$J19/$C19) | L19: =IF($J19<0,"LOSS",IF($K19<0.15,"THIN","OK"))
A21: ACTIVATION BREAK-EVEN
A22: Units that must sell at one event before the KES 7,000 of venue and staff is covered.
A23: SHRINKAGE | B23: AVG PRICE/UNIT | C23: CONTRIBUTION/UNIT before event | D23: UNITS NEEDED | E23: RUNNING AT | F23: GAP
A24: historical 37.3% | B24: =SUM(UNIT_ECONOMICS!$P$7:$P$37)/31 | C24: =(SUM(UNIT_ECONOMICS!$P$7:$P$37)-SUM(UNIT_ECONOMICS!$F$7:$F$37)-SUM(UNIT_ECONOMICS!$F$7:$F$37)*(SHRINK_ACTUAL/(1-SHRINK_ACTUAL))-SUM(UNIT_ECONOMICS!$P$7:$P$37)*FEE_MPESA-SUM(UNIT_ECONOMICS!$P$7:$P$37)*AGENT_RATE)/31 | D24: =IF($C24<=0,"never — negative before the event cost",ROUND(EVENT_COST/$C24,1)) | E24: =UNITS_PER_EVENT | F24: =IF(ISNUMBER($D24),ROUND($D24-$E24,1),"—")
A25: plan 10% | B25: =SUM(UNIT_ECONOMICS!$P$7:$P$37)/31 | C25: =(SUM(UNIT_ECONOMICS!$P$7:$P$37)-SUM(UNIT_ECONOMICS!$F$7:$F$37)-SUM(UNIT_ECONOMICS!$F$7:$F$37)*(SHRINK_PLAN/(1-SHRINK_PLAN))-SUM(UNIT_ECONOMICS!$P$7:$P$37)*FEE_MPESA-SUM(UNIT_ECONOMICS!$P$7:$P$37)*AGENT_RATE)/31 | D25: =IF($C25<=0,"never — negative before the event cost",ROUND(EVENT_COST/$C25,1)) | E25: =UNITS_PER_EVENT | F25: =IF(ISNUMBER($D25),ROUND($D25-$E25,1),"—")
A26: best case 5% | B26: =SUM(UNIT_ECONOMICS!$P$7:$P$37)/31 | C26: =(SUM(UNIT_ECONOMICS!$P$7:$P$37)-SUM(UNIT_ECONOMICS!$F$7:$F$37)-SUM(UNIT_ECONOMICS!$F$7:$F$37)*(0.05/(1-0.05))-SUM(UNIT_ECONOMICS!$P$7:$P$37)*FEE_MPESA-SUM(UNIT_ECONOMICS!$P$7:$P$37)*AGENT_RATE)/31 | D26: =IF($C26<=0,"never — negative before the event cost",ROUND(EVENT_COST/$C26,1)) | E26: =UNITS_PER_EVENT | F26: =IF(ISNUMBER($D26),ROUND($D26-$E26,1),"—")
A28: The activation programme is not a pricing problem.
A29: At the historical shrinkage rate a unit is already loss-making before anyone pays for a venue. At a 10% rate it needs about ten units an event; it is running at three. Either the basket triples, the event cost falls, or the channel is for lead generation and should be funded from a marketing budget rather than expected to pay for itself on unit margin.

Sheet CLOSURE_PLAN
B1: CLOSING THE SKU AND PRICE CHAPTER
B2: Six items. Each has one decision, one owner and one test that proves it closed. Nothing here needs new analysis.
A4: No. | B4: ITEM | C4: TYPE | D4: DECIDED BY | E4: THE DECISION, AND WHAT CLOSES IT | F4: GATE TEST
A5: 1 | B5: Tax status — registered or not | C5: PARAMETER | D5: Accountant | E5: F-9 settles it: bears VAT, does not charge it. GUARDRAILS now carries VAT_REGISTERED = NO and the whole book re-prices from it. CLOSED the moment the accountant confirms in writing; the switch is already built so confirmation changes one cell, not the analysis. | F5: MULT_RETAIL
A6: 2 | B6: Ratify UC-BOG-FCB-028 | C6: ISSUE | D6: Master / CEO | E6: Two physically different cartridges share UC-BOG-FCA-015. Say yes to the proposed number and the split is done. Closes when SKU_REGISTRY shows ISSUED instead of PROPOSED. | F6: G2
A7: 3 | B7: Five impossible cost rows | C7: DATA | D7: Procurement | E7: FLB-012, SQB-013, SQB-014, FCS-017, DFS-024 record landed cost BELOW ex-works. One of the two numbers on each row is wrong — check the supplier invoice, correct whichever is wrong. Five lookups. | F7: G6
A8: 4 | B8: Four SKUs with no landed cost | C8: DATA | D8: Procurement | E8: UF-100, DFS-025, DFS-026, ROT-029. Get carton dimensions and ex-works from the supplier; freight then derives itself. Until then the gate correctly holds them out of the catalogue. | F8: G5
A9: 5 | B9: Aqua Stream carton dimensions | C9: DATA | D9: Supplier | E9: Currently on a comparable carton, BASIS = ESTIMATE. Real dimensions move it to DERIVED and will RAISE the freight, because a 1200GPD twin-membrane unit is larger than the 800G it was compared to. | F9: BASIS
A10: 6 | B10: Beauty Faucet Filter | C10: RULING | D10: CEO | E10: Same parent as UC-SKW-DFS-024, or a separate product? One sentence either way. | F10: G4
B12: WHAT "CLOSED" MEANS
B13: The chapter is closed when GATE shows zero BLOCKED rows and SKU_REGISTRY shows zero PROPOSED rows. Not when a meeting agrees — when the file says so. Everything above is a data errand or a one-line ruling; none of it needs further analysis, and none of it blocks the unit-economics work.
B15: AND ONE CORRECTION I OWE
B16: The guardrail shipped on 17 Sep derived MULT_RETAIL = 2.00 from a 1.5660 floor. F-9 (FINAL, 9 Sep 2026) had already settled the floor at 1.35 — the 31 Aug recut had counted VAT twice. MULT_RETAIL is now 1.73 and every price in this file has moved down accordingly, by 13.5%. The method was right; the input was stale, because I did not re-read the development record before building. That is the same failure this project keeps finding: one value living in two places.

Sheet GATE
A1: GATE — every parent, every rule, live. A product reaches the catalogue only when PUBLISH says GO.
A2: PRICE_ACTUAL is yours to set. PRICE_MIN is the FLOOR-BINDING minimum (cost x R4_FLOOR / deepest tier). The gate only checks that actual is not BELOW it - judgement may price above it freely. MULT_RETAIL (2.00) is the engine default that lands safely above PRICE_MIN.
A4: PARENT_SKU | B4: MODEL | C4: STOCK_STATUS | D4: COST_KES | E4: COST_BASIS | F4: PRICE_MIN (floor-binding) | G4: PRICE_ACTUAL | H4: HEADROOM | I4: MAX_DISC | J4: WHSL_PUB | K4: CORP_PUB | L4: INFL_PUB | M4: G1 | N4: G2 | O4: G5 | P4: G6 | Q4: G7 | R4: G8 | S4: PUBLISH | T4: WHY NOT
A5: UC-HOU-PHRO-001 | B5: =IFERROR(INDEX(LANDED_COST_BUILD!$B:$B,MATCH($A5,LANDED_COST_BUILD!$A:$A,0)),"") | C5: =IFERROR(INDEX(LANDED_COST_BUILD!$C:$C,MATCH($A5,LANDED_COST_BUILD!$A:$A,0)),"") | D5: =IFERROR(IF(INDEX(LANDED_COST_BUILD!$O:$O,MATCH($A5,LANDED_COST_BUILD!$A:$A,0))="","",INDEX(LANDED_COST_BUILD!$O:$O,MATCH($A5,LANDED_COST_BUILD!$A:$A,0))*FX_USD_KES),"") | E5: =IFERROR(LEFT(INDEX(LANDED_COST_BUILD!$P:$P,MATCH($A5,LANDED_COST_BUILD!$A:$A,0)),FIND(" ",INDEX(LANDED_COST_BUILD!$P:$P,MATCH($A5,LANDED_COST_BUILD!$A:$A,0))&" ")-1),"") | F5: =IF($D5="","",ROUNDUP($D5*R4_FLOOR/MIN_TIER_RATE,0)) | G5: =IFERROR(INDEX('SKU with PRICES'!$M:$M,MATCH($A5,'SKU with PRICES'!$H:$H,0)),"") | H5: =IF(OR($D5="",$G5=""),"",ROUND($G5/($D5*R4_FLOOR)-1,4)) | I5: =IF(OR($D5="",$G5=""),"",MAX(0,1-($D5*R4_FLOOR/$G5))) | J5: =IFERROR(INDEX('SKU with PRICES'!$O:$O,MATCH($A5,'SKU with PRICES'!$H:$H,0)),"") | K5: =IFERROR(INDEX('SKU with PRICES'!$Q:$Q,MATCH($A5,'SKU with PRICES'!$H:$H,0)),"") | L5: =IFERROR(INDEX('SKU with PRICES'!$S:$S,MATCH($A5,'SKU with PRICES'!$H:$H,0)),"") | M5: =IF(AND(LEFT($A5,3)="UC-",LEN($A5)>=13),"PASS","FAIL") | N5: =IF(COUNTIF($A$5:$A$99,$A5)=1,"PASS","FAIL") | O5: =IF($E5="NONE","FAIL",IF($E5="RECORDED","WARN","PASS")) | P5: =IFERROR(IF(INDEX(LANDED_COST_BUILD!$O:$O,MATCH($A5,LANDED_COST_BUILD!$A:$A,0))="","n/a",IF(INDEX(LANDED_COST_BUILD!$O:$O,MATCH($A5,LANDED_COST_BUILD!$A:$A,0))<INDEX(LANDED_COST_BUILD!$G:$G,MATCH($A5,LANDED_COST_BUILD!$A:$A,0)),"FAIL","PASS")),"n/a") | Q5: =IF(OR($F5="",$G5=""),"n/a",IF($G5>=$F5,"PASS","FAIL")) | R5: =IF($D5="","n/a",IF(AND(N($J5)>=$D5*R4_FLOOR,N($K5)>=$D5*R4_FLOOR,N($L5)>=$D5*R4_FLOOR),"PASS","FAIL")) | S5: =IF(COUNTIF($M5:$R5,"FAIL")>0,"BLOCKED",IF($D5="","HOLD - no cost","GO")) | T5: =IF($S5="GO","",IF($M5="FAIL","SKU format. ","")&IF($N5="FAIL","Duplicate SKU. ","")&IF($P5="FAIL","Landed cost is below ex-works - impossible. ","")&IF($Q5="FAIL","Retail is below the floor-binding minimum. ","")&IF($R5="FAIL","A published discount tier breaches the floor. ","")&IF($D5="","No cost recorded - cannot be gated or published. ",""))
A6: UC-HOU-URO-001 | B6: =IFERROR(INDEX(LANDED_COST_BUILD!$B:$B,MATCH($A6,LANDED_COST_BUILD!$A:$A,0)),"") | C6: =IFERROR(INDEX(LANDED_COST_BUILD!$C:$C,MATCH($A6,LANDED_COST_BUILD!$A:$A,0)),"") | D6: =IFERROR(IF(INDEX(LANDED_COST_BUILD!$O:$O,MATCH($A6,LANDED_COST_BUILD!$A:$A,0))="","",INDEX(LANDED_COST_BUILD!$O:$O,MATCH($A6,LANDED_COST_BUILD!$A:$A,0))*FX_USD_KES),"") | E6: =IFERROR(LEFT(INDEX(LANDED_COST_BUILD!$P:$P,MATCH($A6,LANDED_COST_BUILD!$A:$A,0)),FIND(" ",INDEX(LANDED_COST_BUILD!$P:$P,MATCH($A6,LANDED_COST_BUILD!$A:$A,0))&" ")-1),"") | F6: =IF($D6="","",ROUNDUP($D6*R4_FLOOR/MIN_TIER_RATE,0)) | G6: =IFERROR(INDEX('SKU with PRICES'!$M:$M,MATCH($A6,'SKU with PRICES'!$H:$H,0)),"") | H6: =IF(OR($D6="",$G6=""),"",ROUND($G6/($D6*R4_FLOOR)-1,4)) | I6: =IF(OR($D6="",$G6=""),"",MAX(0,1-($D6*R4_FLOOR/$G6))) | J6: =IFERROR(INDEX('SKU with PRICES'!$O:$O,MATCH($A6,'SKU with PRICES'!$H:$H,0)),"") | K6: =IFERROR(INDEX('SKU with PRICES'!$Q:$Q,MATCH($A6,'SKU with PRICES'!$H:$H,0)),"") | L6: =IFERROR(INDEX('SKU with PRICES'!$S:$S,MATCH($A6,'SKU with PRICES'!$H:$H,0)),"") | M6: =IF(AND(LEFT($A6,3)="UC-",LEN($A6)>=13),"PASS","FAIL") | N6: =IF(COUNTIF($A$5:$A$99,$A6)=1,"PASS","FAIL") | O6: =IF($E6="NONE","FAIL",IF($E6="RECORDED","WARN","PASS")) | P6: =IFERROR(IF(INDEX(LANDED_COST_BUILD!$O:$O,MATCH($A6,LANDED_COST_BUILD!$A:$A,0))="","n/a",IF(INDEX(LANDED_COST_BUILD!$O:$O,MATCH($A6,LANDED_COST_BUILD!$A:$A,0))<INDEX(LANDED_COST_BUILD!$G:$G,MATCH($A6,LANDED_COST_BUILD!$A:$A,0)),"FAIL","PASS")),"n/a") | Q6: =IF(OR($F6="",$G6=""),"n/a",IF($G6>=$F6,"PASS","FAIL")) | R6: =IF($D6="","n/a",IF(AND(N($J6)>=$D6*R4_FLOOR,N($K6)>=$D6*R4_FLOOR,N($L6)>=$D6*R4_FLOOR),"PASS","FAIL")) | S6: =IF(COUNTIF($M6:$R6,"FAIL")>0,"BLOCKED",IF($D6="","HOLD - no cost","GO")) | T6: =IF($S6="GO","",IF($M6="FAIL","SKU format. ","")&IF($N6="FAIL","Duplicate SKU. ","")&IF($P6="FAIL","Landed cost is below ex-works - impossible. ","")&IF($Q6="FAIL","Retail is below the floor-binding minimum. ","")&IF($R6="FAIL","A published discount tier breaches the floor. ","")&IF($D6="","No cost recorded - cannot be gated or published. ",""))
A7: UC-HOU-URO-002 | B7: =IFERROR(INDEX(LANDED_COST_BUILD!$B:$B,MATCH($A7,LANDED_COST_BUILD!$A:$A,0)),"") | C7: =IFERROR(INDEX(LANDED_COST_BUILD!$C:$C,MATCH($A7,LANDED_COST_BUILD!$A:$A,0)),"") | D7: =IFERROR(IF(INDEX(LANDED_COST_BUILD!$O:$O,MATCH($A7,LANDED_COST_BUILD!$A:$A,0))="","",INDEX(LANDED_COST_BUILD!$O:$O,MATCH($A7,LANDED_COST_BUILD!$A:$A,0))*FX_USD_KES),"") | E7: =IFERROR(LEFT(INDEX(LANDED_COST_BUILD!$P:$P,MATCH($A7,LANDED_COST_BUILD!$A:$A,0)),FIND(" ",INDEX(LANDED_COST_BUILD!$P:$P,MATCH($A7,LANDED_COST_BUILD!$A:$A,0))&" ")-1),"") | F7: =IF($D7="","",ROUNDUP($D7*R4_FLOOR/MIN_TIER_RATE,0)) | G7: =IFERROR(INDEX('SKU with PRICES'!$M:$M,MATCH($A7,'SKU with PRICES'!$H:$H,0)),"") | H7: =IF(OR($D7="",$G7=""),"",ROUND($G7/($D7*R4_FLOOR)-1,4)) | I7: =IF(OR($D7="",$G7=""),"",MAX(0,1-($D7*R4_FLOOR/$G7))) | J7: =IFERROR(INDEX('SKU with PRICES'!$O:$O,MATCH($A7,'SKU with PRICES'!$H:$H,0)),"") | K7: =IFERROR(INDEX('SKU with PRICES'!$Q:$Q,MATCH($A7,'SKU with PRICES'!$H:$H,0)),"") | L7: =IFERROR(INDEX('SKU with PRICES'!$S:$S,MATCH($A7,'SKU with PRICES'!$H:$H,0)),"") | M7: =IF(AND(LEFT($A7,3)="UC-",LEN($A7)>=13),"PASS","FAIL") | N7: =IF(COUNTIF($A$5:$A$99,$A7)=1,"PASS","FAIL") | O7: =IF($E7="NONE","FAIL",IF($E7="RECORDED","WARN","PASS")) | P7: =IFERROR(IF(INDEX(LANDED_COST_BUILD!$O:$O,MATCH($A7,LANDED_COST_BUILD!$A:$A,0))="","n/a",IF(INDEX(LANDED_COST_BUILD!$O:$O,MATCH($A7,LANDED_COST_BUILD!$A:$A,0))<INDEX(LANDED_COST_BUILD!$G:$G,MATCH($A7,LANDED_COST_BUILD!$A:$A,0)),"FAIL","PASS")),"n/a") | Q7: =IF(OR($F7="",$G7=""),"n/a",IF($G7>=$F7,"PASS","FAIL")) | R7: =IF($D7="","n/a",IF(AND(N($J7)>=$D7*R4_FLOOR,N($K7)>=$D7*R4_FLOOR,N($L7)>=$D7*R4_FLOOR),"PASS","FAIL")) | S7: =IF(COUNTIF($M7:$R7,"FAIL")>0,"BLOCKED",IF($D7="","HOLD - no cost","GO")) | T7: =IF($S7="GO","",IF($M7="FAIL","SKU format. ","")&IF($N7="FAIL","Duplicate SKU. ","")&IF($P7="FAIL","Landed cost is below ex-works - impossible. ","")&IF($Q7="FAIL","Retail is below the floor-binding minimum. ","")&IF($R7="FAIL","A published discount tier breaches the floor. ","")&IF($D7="","No cost recorded - cannot be gated or published. ",""))
A8: UC-HOU-ROS-001 | B8: =IFERROR(INDEX(LANDED_COST_BUILD!$B:$B,MATCH($A8,LANDED_COST_BUILD!$A:$A,0)),"") | C8: =IFERROR(INDEX(LANDED_COST_BUILD!$C:$C,MATCH($A8,LANDED_COST_BUILD!$A:$A,0)),"") | D8: =IFERROR(IF(INDEX(LANDED_COST_BUILD!$O:$O,MATCH($A8,LANDED_COST_BUILD!$A:$A,0))="","",INDEX(LANDED_COST_BUILD!$O:$O,MATCH($A8,LANDED_COST_BUILD!$A:$A,0))*FX_USD_KES),"") | E8: =IFERROR(LEFT(INDEX(LANDED_COST_BUILD!$P:$P,MATCH($A8,LANDED_COST_BUILD!$A:$A,0)),FIND(" ",INDEX(LANDED_COST_BUILD!$P:$P,MATCH($A8,LANDED_COST_BUILD!$A:$A,0))&" ")-1),"") | F8: =IF($D8="","",ROUNDUP($D8*R4_FLOOR/MIN_TIER_RATE,0)) | G8: =IFERROR(INDEX('SKU with PRICES'!$M:$M,MATCH($A8,'SKU with PRICES'!$H:$H,0)),"") | H8: =IF(OR($D8="",$G8=""),"",ROUND($G8/($D8*R4_FLOOR)-1,4)) | I8: =IF(OR($D8="",$G8=""),"",MAX(0,1-($D8*R4_FLOOR/$G8))) | J8: =IFERROR(INDEX('SKU with PRICES'!$O:$O,MATCH($A8,'SKU with PRICES'!$H:$H,0)),"") | K8: =IFERROR(INDEX('SKU with PRICES'!$Q:$Q,MATCH($A8,'SKU with PRICES'!$H:$H,0)),"") | L8: =IFERROR(INDEX('SKU with PRICES'!$S:$S,MATCH($A8,'SKU with PRICES'!$H:$H,0)),"") | M8: =IF(AND(LEFT($A8,3)="UC-",LEN($A8)>=13),"PASS","FAIL") | N8: =IF(COUNTIF($A$5:$A$99,$A8)=1,"PASS","FAIL") | O8: =IF($E8="NONE","FAIL",IF($E8="RECORDED","WARN","PASS")) | P8: =IFERROR(IF(INDEX(LANDED_COST_BUILD!$O:$O,MATCH($A8,LANDED_COST_BUILD!$A:$A,0))="","n/a",IF(INDEX(LANDED_COST_BUILD!$O:$O,MATCH($A8,LANDED_COST_BUILD!$A:$A,0))<INDEX(LANDED_COST_BUILD!$G:$G,MATCH($A8,LANDED_COST_BUILD!$A:$A,0)),"FAIL","PASS")),"n/a") | Q8: =IF(OR($F8="",$G8=""),"n/a",IF($G8>=$F8,"PASS","FAIL")) | R8: =IF($D8="","n/a",IF(AND(N($J8)>=$D8*R4_FLOOR,N($K8)>=$D8*R4_FLOOR,N($L8)>=$D8*R4_FLOOR),"PASS","FAIL")) | S8: =IF(COUNTIF($M8:$R8,"FAIL")>0,"BLOCKED",IF($D8="","HOLD - no cost","GO")) | T8: =IF($S8="GO","",IF($M8="FAIL","SKU format. ","")&IF($N8="FAIL","Duplicate SKU. ","")&IF($P8="FAIL","Landed cost is below ex-works - impossible. ","")&IF($Q8="FAIL","Retail is below the floor-binding minimum. ","")&IF($R8="FAIL","A published discount tier breaches the floor. ","")&IF($D8="","No cost recorded - cannot be gated or published. ",""))
A9: UC-COM-ROS-002 | B9: =IFERROR(INDEX(LANDED_COST_BUILD!$B:$B,MATCH($A9,LANDED_COST_BUILD!$A:$A,0)),"") | C9: =IFERROR(INDEX(LANDED_COST_BUILD!$C:$C,MATCH($A9,LANDED_COST_BUILD!$A:$A,0)),"") | D9: =IFERROR(IF(INDEX(LANDED_COST_BUILD!$O:$O,MATCH($A9,LANDED_COST_BUILD!$A:$A,0))="","",INDEX(LANDED_COST_BUILD!$O:$O,MATCH($A9,LANDED_COST_BUILD!$A:$A,0))*FX_USD_KES),"") | E9: =IFERROR(LEFT(INDEX(LANDED_COST_BUILD!$P:$P,MATCH($A9,LANDED_COST_BUILD!$A:$A,0)),FIND(" ",INDEX(LANDED_COST_BUILD!$P:$P,MATCH($A9,LANDED_COST_BUILD!$A:$A,0))&" ")-1),"") | F9: =IF($D9="","",ROUNDUP($D9*R4_FLOOR/MIN_TIER_RATE,0)) | G9: =IFERROR(INDEX('SKU with PRICES'!$M:$M,MATCH($A9,'SKU with PRICES'!$H:$H,0)),"") | H9: =IF(OR($D9="",$G9=""),"",ROUND($G9/($D9*R4_FLOOR)-1,4)) | I9: =IF(OR($D9="",$G9=""),"",MAX(0,1-($D9*R4_FLOOR/$G9))) | J9: =IFERROR(INDEX('SKU with PRICES'!$O:$O,MATCH($A9,'SKU with PRICES'!$H:$H,0)),"") | K9: =IFERROR(INDEX('SKU with PRICES'!$Q:$Q,MATCH($A9,'SKU with PRICES'!$H:$H,0)),"") | L9: =IFERROR(INDEX('SKU with PRICES'!$S:$S,MATCH($A9,'SKU with PRICES'!$H:$H,0)),"") | M9: =IF(AND(LEFT($A9,3)="UC-",LEN($A9)>=13),"PASS","FAIL") | N9: =IF(COUNTIF($A$5:$A$99,$A9)=1,"PASS","FAIL") | O9: =IF($E9="NONE","FAIL",IF($E9="RECORDED","WARN","PASS")) | P9: =IFERROR(IF(INDEX(LANDED_COST_BUILD!$O:$O,MATCH($A9,LANDED_COST_BUILD!$A:$A,0))="","n/a",IF(INDEX(LANDED_COST_BUILD!$O:$O,MATCH($A9,LANDED_COST_BUILD!$A:$A,0))<INDEX(LANDED_COST_BUILD!$G:$G,MATCH($A9,LANDED_COST_BUILD!$A:$A,0)),"FAIL","PASS")),"n/a") | Q9: =IF(OR($F9="",$G9=""),"n/a",IF($G9>=$F9,"PASS","FAIL")) | R9: =IF($D9="","n/a",IF(AND(N($J9)>=$D9*R4_FLOOR,N($K9)>=$D9*R4_FLOOR,N($L9)>=$D9*R4_FLOOR),"PASS","FAIL")) | S9: =IF(COUNTIF($M9:$R9,"FAIL")>0,"BLOCKED",IF($D9="","HOLD - no cost","GO")) | T9: =IF($S9="GO","",IF($M9="FAIL","SKU format. ","")&IF($N9="FAIL","Duplicate SKU. ","")&IF($P9="FAIL","Landed cost is below ex-works - impossible. ","")&IF($Q9="FAIL","Retail is below the floor-binding minimum. ","")&IF($R9="FAIL","A published discount tier breaches the floor. ","")&IF($D9="","No cost recorded - cannot be gated or published. ",""))
A10: UC-HOU-WPF-003 | B10: =IFERROR(INDEX(LANDED_COST_BUILD!$B:$B,MATCH($A10,LANDED_COST_BUILD!$A:$A,0)),"") | C10: =IFERROR(INDEX(LANDED_COST_BUILD!$C:$C,MATCH($A10,LANDED_COST_BUILD!$A:$A,0)),"") | D10: =IFERROR(IF(INDEX(LANDED_COST_BUILD!$O:$O,MATCH($A10,LANDED_COST_BUILD!$A:$A,0))="","",INDEX(LANDED_COST_BUILD!$O:$O,MATCH($A10,LANDED_COST_BUILD!$A:$A,0))*FX_USD_KES),"") | E10: =IFERROR(LEFT(INDEX(LANDED_COST_BUILD!$P:$P,MATCH($A10,LANDED_COST_BUILD!$A:$A,0)),FIND(" ",INDEX(LANDED_COST_BUILD!$P:$P,MATCH($A10,LANDED_COST_BUILD!$A:$A,0))&" ")-1),"") | F10: =IF($D10="","",ROUNDUP($D10*R4_FLOOR/MIN_TIER_RATE,0)) | G10: =IFERROR(INDEX('SKU with PRICES'!$M:$M,MATCH($A10,'SKU with PRICES'!$H:$H,0)),"") | H10: =IF(OR($D10="",$G10=""),"",ROUND($G10/($D10*R4_FLOOR)-1,4)) | I10: =IF(OR($D10="",$G10=""),"",MAX(0,1-($D10*R4_FLOOR/$G10))) | J10: =IFERROR(INDEX('SKU with PRICES'!$O:$O,MATCH($A10,'SKU with PRICES'!$H:$H,0)),"") | K10: =IFERROR(INDEX('SKU with PRICES'!$Q:$Q,MATCH($A10,'SKU with PRICES'!$H:$H,0)),"") | L10: =IFERROR(INDEX('SKU with PRICES'!$S:$S,MATCH($A10,'SKU with PRICES'!$H:$H,0)),"") | M10: =IF(AND(LEFT($A10,3)="UC-",LEN($A10)>=13),"PASS","FAIL") | N10: =IF(COUNTIF($A$5:$A$99,$A10)=1,"PASS","FAIL") | O10: =IF($E10="NONE","FAIL",IF($E10="RECORDED","WARN","PASS")) | P10: =IFERROR(IF(INDEX(LANDED_COST_BUILD!$O:$O,MATCH($A10,LANDED_COST_BUILD!$A:$A,0))="","n/a",IF(INDEX(LANDED_COST_BUILD!$O:$O,MATCH($A10,LANDED_COST_BUILD!$A:$A,0))<INDEX(LANDED_COST_BUILD!$G:$G,MATCH($A10,LANDED_COST_BUILD!$A:$A,0)),"FAIL","PASS")),"n/a") | Q10: =IF(OR($F10="",$G10=""),"n/a",IF($G10>=$F10,"PASS","FAIL")) | R10: =IF($D10="","n/a",IF(AND(N($J10)>=$D10*R4_FLOOR,N($K10)>=$D10*R4_FLOOR,N($L10)>=$D10*R4_FLOOR),"PASS","FAIL")) | S10: =IF(COUNTIF($M10:$R10,"FAIL")>0,"BLOCKED",IF($D10="","HOLD - no cost","GO")) | T10: =IF($S10="GO","",IF($M10="FAIL","SKU format. ","")&IF($N10="FAIL","Duplicate SKU. ","")&IF($P10="FAIL","Landed cost is below ex-works - impossible. ","")&IF($Q10="FAIL","Retail is below the floor-binding minimum. ","")&IF($R10="FAIL","A published discount tier breaches the floor. ","")&IF($D10="","No cost recorded - cannot be gated or published. ",""))
A11: UC-HOU-USF-004 | B11: =IFERROR(INDEX(LANDED_COST_BUILD!$B:$B,MATCH($A11,LANDED_COST_BUILD!$A:$A,0)),"") | C11: =IFERROR(INDEX(LANDED_COST_BUILD!$C:$C,MATCH($A11,LANDED_COST_BUILD!$A:$A,0)),"") | D11: =IFERROR(IF(INDEX(LANDED_COST_BUILD!$O:$O,MATCH($A11,LANDED_COST_BUILD!$A:$A,0))="","",INDEX(LANDED_COST_BUILD!$O:$O,MATCH($A11,LANDED_COST_BUILD!$A:$A,0))*FX_USD_KES),"") | E11: =IFERROR(LEFT(INDEX(LANDED_COST_BUILD!$P:$P,MATCH($A11,LANDED_COST_BUILD!$A:$A,0)),FIND(" ",INDEX(LANDED_COST_BUILD!$P:$P,MATCH($A11,LANDED_COST_BUILD!$A:$A,0))&" ")-1),"") | F11: =IF($D11="","",ROUNDUP($D11*R4_FLOOR/MIN_TIER_RATE,0)) | G11: =IFERROR(INDEX('SKU with PRICES'!$M:$M,MATCH($A11,'SKU with PRICES'!$H:$H,0)),"") | H11: =IF(OR($D11="",$G11=""),"",ROUND($G11/($D11*R4_FLOOR)-1,4)) | I11: =IF(OR($D11="",$G11=""),"",MAX(0,1-($D11*R4_FLOOR/$G11))) | J11: =IFERROR(INDEX('SKU with PRICES'!$O:$O,MATCH($A11,'SKU with PRICES'!$H:$H,0)),"") | K11: =IFERROR(INDEX('SKU with PRICES'!$Q:$Q,MATCH($A11,'SKU with PRICES'!$H:$H,0)),"") | L11: =IFERROR(INDEX('SKU with PRICES'!$S:$S,MATCH($A11,'SKU with PRICES'!$H:$H,0)),"") | M11: =IF(AND(LEFT($A11,3)="UC-",LEN($A11)>=13),"PASS","FAIL") | N11: =IF(COUNTIF($A$5:$A$99,$A11)=1,"PASS","FAIL") | O11: =IF($E11="NONE","FAIL",IF($E11="RECORDED","WARN","PASS")) | P11: =IFERROR(IF(INDEX(LANDED_COST_BUILD!$O:$O,MATCH($A11,LANDED_COST_BUILD!$A:$A,0))="","n/a",IF(INDEX(LANDED_COST_BUILD!$O:$O,MATCH($A11,LANDED_COST_BUILD!$A:$A,0))<INDEX(LANDED_COST_BUILD!$G:$G,MATCH($A11,LANDED_COST_BUILD!$A:$A,0)),"FAIL","PASS")),"n/a") | Q11: =IF(OR($F11="",$G11=""),"n/a",IF($G11>=$F11,"PASS","FAIL")) | R11: =IF($D11="","n/a",IF(AND(N($J11)>=$D11*R4_FLOOR,N($K11)>=$D11*R4_FLOOR,N($L11)>=$D11*R4_FLOOR),"PASS","FAIL")) | S11: =IF(COUNTIF($M11:$R11,"FAIL")>0,"BLOCKED",IF($D11="","HOLD - no cost","GO")) | T11: =IF($S11="GO","",IF($M11="FAIL","SKU format. ","")&IF($N11="FAIL","Duplicate SKU. ","")&IF($P11="FAIL","Landed cost is below ex-works - impossible. ","")&IF($Q11="FAIL","Retail is below the floor-binding minimum. ","")&IF($R11="FAIL","A published discount tier breaches the floor. ","")&IF($D11="","No cost recorded - cannot be gated or published. ",""))
A12: UC-HOU-TAP-005 | B12: =IFERROR(INDEX(LANDED_COST_BUILD!$B:$B,MATCH($A12,LANDED_COST_BUILD!$A:$A,0)),"") | C12: =IFERROR(INDEX(LANDED_COST_BUILD!$C:$C,MATCH($A12,LANDED_COST_BUILD!$A:$A,0)),"") | D12: =IFERROR(IF(INDEX(LANDED_COST_BUILD!$O:$O,MATCH($A12,LANDED_COST_BUILD!$A:$A,0))="","",INDEX(LANDED_COST_BUILD!$O:$O,MATCH($A12,LANDED_COST_BUILD!$A:$A,0))*FX_USD_KES),"") | E12: =IFERROR(LEFT(INDEX(LANDED_COST_BUILD!$P:$P,MATCH($A12,LANDED_COST_BUILD!$A:$A,0)),FIND(" ",INDEX(LANDED_COST_BUILD!$P:$P,MATCH($A12,LANDED_COST_BUILD!$A:$A,0))&" ")-1),"") | F12: =IF($D12="","",ROUNDUP($D12*R4_FLOOR/MIN_TIER_RATE,0)) | G12: =IFERROR(INDEX('SKU with PRICES'!$M:$M,MATCH($A12,'SKU with PRICES'!$H:$H,0)),"") | H12: =IF(OR($D12="",$G12=""),"",ROUND($G12/($D12*R4_FLOOR)-1,4)) | I12: =IF(OR($D12="",$G12=""),"",MAX(0,1-($D12*R4_FLOOR/$G12))) | J12: =IFERROR(INDEX('SKU with PRICES'!$O:$O,MATCH($A12,'SKU with PRICES'!$H:$H,0)),"") | K12: =IFERROR(INDEX('SKU with PRICES'!$Q:$Q,MATCH($A12,'SKU with PRICES'!$H:$H,0)),"") | L12: =IFERROR(INDEX('SKU with PRICES'!$S:$S,MATCH($A12,'SKU with PRICES'!$H:$H,0)),"") | M12: =IF(AND(LEFT($A12,3)="UC-",LEN($A12)>=13),"PASS","FAIL") | N12: =IF(COUNTIF($A$5:$A$99,$A12)=1,"PASS","FAIL") | O12: =IF($E12="NONE","FAIL",IF($E12="RECORDED","WARN","PASS")) | P12: =IFERROR(IF(INDEX(LANDED_COST_BUILD!$O:$O,MATCH($A12,LANDED_COST_BUILD!$A:$A,0))="","n/a",IF(INDEX(LANDED_COST_BUILD!$O:$O,MATCH($A12,LANDED_COST_BUILD!$A:$A,0))<INDEX(LANDED_COST_BUILD!$G:$G,MATCH($A12,LANDED_COST_BUILD!$A:$A,0)),"FAIL","PASS")),"n/a") | Q12: =IF(OR($F12="",$G12=""),"n/a",IF($G12>=$F12,"PASS","FAIL")) | R12: =IF($D12="","n/a",IF(AND(N($J12)>=$D12*R4_FLOOR,N($K12)>=$D12*R4_FLOOR,N($L12)>=$D12*R4_FLOOR),"PASS","FAIL")) | S12: =IF(COUNTIF($M12:$R12,"FAIL")>0,"BLOCKED",IF($D12="","HOLD - no cost","GO")) | T12: =IF($S12="GO","",IF($M12="FAIL","SKU format. ","")&IF($N12="FAIL","Duplicate SKU. ","")&IF($P12="FAIL","Landed cost is below ex-works - impossible. ","")&IF($Q12="FAIL","Retail is below the floor-binding minimum. ","")&IF($R12="FAIL","A published discount tier breaches the floor. ","")&IF($D12="","No cost recorded - cannot be gated or published. ",""))
A13: UC-HOU-TAPF-006 | B13: =IFERROR(INDEX(LANDED_COST_BUILD!$B:$B,MATCH($A13,LANDED_COST_BUILD!$A:$A,0)),"") | C13: =IFERROR(INDEX(LANDED_COST_BUILD!$C:$C,MATCH($A13,LANDED_COST_BUILD!$A:$A,0)),"") | D13: =IFERROR(IF(INDEX(LANDED_COST_BUILD!$O:$O,MATCH($A13,LANDED_COST_BUILD!$A:$A,0))="","",INDEX(LANDED_COST_BUILD!$O:$O,MATCH($A13,LANDED_COST_BUILD!$A:$A,0))*FX_USD_KES),"") | E13: =IFERROR(LEFT(INDEX(LANDED_COST_BUILD!$P:$P,MATCH($A13,LANDED_COST_BUILD!$A:$A,0)),FIND(" ",INDEX(LANDED_COST_BUILD!$P:$P,MATCH($A13,LANDED_COST_BUILD!$A:$A,0))&" ")-1),"") | F13: =IF($D13="","",ROUNDUP($D13*R4_FLOOR/MIN_TIER_RATE,0)) | G13: =IFERROR(INDEX('SKU with PRICES'!$M:$M,MATCH($A13,'SKU with PRICES'!$H:$H,0)),"") | H13: =IF(OR($D13="",$G13=""),"",ROUND($G13/($D13*R4_FLOOR)-1,4)) | I13: =IF(OR($D13="",$G13=""),"",MAX(0,1-($D13*R4_FLOOR/$G13))) | J13: =IFERROR(INDEX('SKU with PRICES'!$O:$O,MATCH($A13,'SKU with PRICES'!$H:$H,0)),"") | K13: =IFERROR(INDEX('SKU with PRICES'!$Q:$Q,MATCH($A13,'SKU with PRICES'!$H:$H,0)),"") | L13: =IFERROR(INDEX('SKU with PRICES'!$S:$S,MATCH($A13,'SKU with PRICES'!$H:$H,0)),"") | M13: =IF(AND(LEFT($A13,3)="UC-",LEN($A13)>=13),"PASS","FAIL") | N13: =IF(COUNTIF($A$5:$A$99,$A13)=1,"PASS","FAIL") | O13: =IF($E13="NONE","FAIL",IF($E13="RECORDED","WARN","PASS")) | P13: =IFERROR(IF(INDEX(LANDED_COST_BUILD!$O:$O,MATCH($A13,LANDED_COST_BUILD!$A:$A,0))="","n/a",IF(INDEX(LANDED_COST_BUILD!$O:$O,MATCH($A13,LANDED_COST_BUILD!$A:$A,0))<INDEX(LANDED_COST_BUILD!$G:$G,MATCH($A13,LANDED_COST_BUILD!$A:$A,0)),"FAIL","PASS")),"n/a") | Q13: =IF(OR($F13="",$G13=""),"n/a",IF($G13>=$F13,"PASS","FAIL")) | R13: =IF($D13="","n/a",IF(AND(N($J13)>=$D13*R4_FLOOR,N($K13)>=$D13*R4_FLOOR,N($L13)>=$D13*R4_FLOOR),"PASS","FAIL")) | S13: =IF(COUNTIF($M13:$R13,"FAIL")>0,"BLOCKED",IF($D13="","HOLD - no cost","GO")) | T13: =IF($S13="GO","",IF($M13="FAIL","SKU format. ","")&IF($N13="FAIL","Duplicate SKU. ","")&IF($P13="FAIL","Landed cost is below ex-works - impossible. ","")&IF($Q13="FAIL","Retail is below the floor-binding minimum. ","")&IF($R13="FAIL","A published discount tier breaches the floor. ","")&IF($D13="","No cost recorded - cannot be gated or published. ",""))
A14: UC-HOU-WDFS-006 | B14: =IFERROR(INDEX(LANDED_COST_BUILD!$B:$B,MATCH($A14,LANDED_COST_BUILD!$A:$A,0)),"") | C14: =IFERROR(INDEX(LANDED_COST_BUILD!$C:$C,MATCH($A14,LANDED_COST_BUILD!$A:$A,0)),"") | D14: =IFERROR(IF(INDEX(LANDED_COST_BUILD!$O:$O,MATCH($A14,LANDED_COST_BUILD!$A:$A,0))="","",INDEX(LANDED_COST_BUILD!$O:$O,MATCH($A14,LANDED_COST_BUILD!$A:$A,0))*FX_USD_KES),"") | E14: =IFERROR(LEFT(INDEX(LANDED_COST_BUILD!$P:$P,MATCH($A14,LANDED_COST_BUILD!$A:$A,0)),FIND(" ",INDEX(LANDED_COST_BUILD!$P:$P,MATCH($A14,LANDED_COST_BUILD!$A:$A,0))&" ")-1),"") | F14: =IF($D14="","",ROUNDUP($D14*R4_FLOOR/MIN_TIER_RATE,0)) | G14: =IFERROR(INDEX('SKU with PRICES'!$M:$M,MATCH($A14,'SKU with PRICES'!$H:$H,0)),"") | H14: =IF(OR($D14="",$G14=""),"",ROUND($G14/($D14*R4_FLOOR)-1,4)) | I14: =IF(OR($D14="",$G14=""),"",MAX(0,1-($D14*R4_FLOOR/$G14))) | J14: =IFERROR(INDEX('SKU with PRICES'!$O:$O,MATCH($A14,'SKU with PRICES'!$H:$H,0)),"") | K14: =IFERROR(INDEX('SKU with PRICES'!$Q:$Q,MATCH($A14,'SKU with PRICES'!$H:$H,0)),"") | L14: =IFERROR(INDEX('SKU with PRICES'!$S:$S,MATCH($A14,'SKU with PRICES'!$H:$H,0)),"") | M14: =IF(AND(LEFT($A14,3)="UC-",LEN($A14)>=13),"PASS","FAIL") | N14: =IF(COUNTIF($A$5:$A$99,$A14)=1,"PASS","FAIL") | O14: =IF($E14="NONE","FAIL",IF($E14="RECORDED","WARN","PASS")) | P14: =IFERROR(IF(INDEX(LANDED_COST_BUILD!$O:$O,MATCH($A14,LANDED_COST_BUILD!$A:$A,0))="","n/a",IF(INDEX(LANDED_COST_BUILD!$O:$O,MATCH($A14,LANDED_COST_BUILD!$A:$A,0))<INDEX(LANDED_COST_BUILD!$G:$G,MATCH($A14,LANDED_COST_BUILD!$A:$A,0)),"FAIL","PASS")),"n/a") | Q14: =IF(OR($F14="",$G14=""),"n/a",IF($G14>=$F14,"PASS","FAIL")) | R14: =IF($D14="","n/a",IF(AND(N($J14)>=$D14*R4_FLOOR,N($K14)>=$D14*R4_FLOOR,N($L14)>=$D14*R4_FLOOR),"PASS","FAIL")) | S14: =IF(COUNTIF($M14:$R14,"FAIL")>0,"BLOCKED",IF($D14="","HOLD - no cost","GO")) | T14: =IF($S14="GO","",IF($M14="FAIL","SKU format. ","")&IF($N14="FAIL","Duplicate SKU. ","")&IF($P14="FAIL","Landed cost is below ex-works - impossible. ","")&IF($Q14="FAIL","Retail is below the floor-binding minimum. ","")&IF($R14="FAIL","A published discount tier breaches the floor. ","")&IF($D14="","No cost recorded - cannot be gated or published. ",""))
A15: UC-HOU-DF-007 | B15: =IFERROR(INDEX(LANDED_COST_BUILD!$B:$B,MATCH($A15,LANDED_COST_BUILD!$A:$A,0)),"") | C15: =IFERROR(INDEX(LANDED_COST_BUILD!$C:$C,MATCH($A15,LANDED_COST_BUILD!$A:$A,0)),"") | D15: =IFERROR(IF(INDEX(LANDED_COST_BUILD!$O:$O,MATCH($A15,LANDED_COST_BUILD!$A:$A,0))="","",INDEX(LANDED_COST_BUILD!$O:$O,MATCH($A15,LANDED_COST_BUILD!$A:$A,0))*FX_USD_KES),"") | E15: =IFERROR(LEFT(INDEX(LANDED_COST_BUILD!$P:$P,MATCH($A15,LANDED_COST_BUILD!$A:$A,0)),FIND(" ",INDEX(LANDED_COST_BUILD!$P:$P,MATCH($A15,LANDED_COST_BUILD!$A:$A,0))&" ")-1),"") | F15: =IF($D15="","",ROUNDUP($D15*R4_FLOOR/MIN_TIER_RATE,0)) | G15: =IFERROR(INDEX('SKU with PRICES'!$M:$M,MATCH($A15,'SKU with PRICES'!$H:$H,0)),"") | H15: =IF(OR($D15="",$G15=""),"",ROUND($G15/($D15*R4_FLOOR)-1,4)) | I15: =IF(OR($D15="",$G15=""),"",MAX(0,1-($D15*R4_FLOOR/$G15))) | J15: =IFERROR(INDEX('SKU with PRICES'!$O:$O,MATCH($A15,'SKU with PRICES'!$H:$H,0)),"") | K15: =IFERROR(INDEX('SKU with PRICES'!$Q:$Q,MATCH($A15,'SKU with PRICES'!$H:$H,0)),"") | L15: =IFERROR(INDEX('SKU with PRICES'!$S:$S,MATCH($A15,'SKU with PRICES'!$H:$H,0)),"") | M15: =IF(AND(LEFT($A15,3)="UC-",LEN($A15)>=13),"PASS","FAIL") | N15: =IF(COUNTIF($A$5:$A$99,$A15)=1,"PASS","FAIL") | O15: =IF($E15="NONE","FAIL",IF($E15="RECORDED","WARN","PASS")) | P15: =IFERROR(IF(INDEX(LANDED_COST_BUILD!$O:$O,MATCH($A15,LANDED_COST_BUILD!$A:$A,0))="","n/a",IF(INDEX(LANDED_COST_BUILD!$O:$O,MATCH($A15,LANDED_COST_BUILD!$A:$A,0))<INDEX(LANDED_COST_BUILD!$G:$G,MATCH($A15,LANDED_COST_BUILD!$A:$A,0)),"FAIL","PASS")),"n/a") | Q15: =IF(OR($F15="",$G15=""),"n/a",IF($G15>=$F15,"PASS","FAIL")) | R15: =IF($D15="","n/a",IF(AND(N($J15)>=$D15*R4_FLOOR,N($K15)>=$D15*R4_FLOOR,N($L15)>=$D15*R4_FLOOR),"PASS","FAIL")) | S15: =IF(COUNTIF($M15:$R15,"FAIL")>0,"BLOCKED",IF($D15="","HOLD - no cost","GO")) | T15: =IF($S15="GO","",IF($M15="FAIL","SKU format. ","")&IF($N15="FAIL","Duplicate SKU. ","")&IF($P15="FAIL","Landed cost is below ex-works - impossible. ","")&IF($Q15="FAIL","Retail is below the floor-binding minimum. ","")&IF($R15="FAIL","A published discount tier breaches the floor. ","")&IF($D15="","No cost recorded - cannot be gated or published. ",""))
